<?xml version="1.0"?>
<robot xmlns:xacro="http://www.ros.org/wiki/xacro" name="wheel">
    <!-- Wheel Properties -->
    <xacro:property name="M_PI" value="3.1415926535897931"/>
    <xacro:property name="wheel_mass" value="0.158" />
    <xacro:property name="wheel_length" value="0.05" />
    <xacro:property name="wheel_radius" value="0.075" />
    <xacro:macro name="wheel" params="ccw wheel_prefix *joint_pose">
        <link name="${wheel_prefix}_wheel_link">
            <inertial>
                <mass value="${wheel_mass}" />
                <origin xyz="0 0 0" />
                <inertia ixx="${1/12*wheel_mass*(3*wheel_radius*wheel_radius + wheel_length*wheel_length)}"
                    iyy="${1/12*wheel_mass*(3*wheel_radius*wheel_radius + wheel_length*wheel_length)}"
                    izz="${1/2*wheel_mass*wheel_radius*wheel_radius}"
                    ixy="0" ixz="0" iyz="0" />
            </inertial>
            <visual>
                <origin xyz="0 0 0" rpy="0 0 0" />
                <geometry>
                    <xacro:unless value="${ccw == 0}">
                        <mesh filename="package://bixi_description/meshes/mec_f_l.dae" scale="1 1 1"/>
                    </xacro:unless>
                    <xacro:if value="${ccw == 0}">
                        <mesh filename="package://bixi_description/meshes/mec_f_r.dae" scale="1 1 1"/>
                    </xacro:if>
                </geometry>
            </visual>
            <collision>
                <origin xyz="0 0 0" rpy="${M_PI/2} 0 0" />
                <geometry>
                    <cylinder length="${wheel_length}" radius="${wheel_radius}" />
                </geometry>
            </collision>
        </link>

        <gazebo reference="${wheel_prefix}_wheel_link">
            <mu1 value="1.0"/>
            <mu2 value="1.0"/>
            <kp value="10000000.0" />
            <kd value="1.0" />
            <fdir1 value="1 0 0"/>
        </gazebo>

        <joint name="${wheel_prefix}_wheel" type="continuous">
            <parent link="base_link"/>
            <child link="${wheel_prefix}_wheel_link"/>
            <xacro:insert_block name="joint_pose"/>
            <axis xyz="0 1 0" rpy="0 0 0" />
        </joint>

        <transmission name="${wheel_prefix}_wheel_trans" type="SimpleTransmission">
            <type>transmission_interface/SimpleTransmission</type>
            <actuator name="${wheel_prefix}_wheel_motor">
                <mechanicalReduction>1</mechanicalReduction>
            </actuator>
            <joint name="${wheel_prefix}_wheel">
                <hardwareInterface>VelocityJointInterface</hardwareInterface>
            </joint>
        </transmission>
    </xacro:macro>
</robot>
